Workbook

Sheet Test Scenario Summary
A1: Student ID | B1: 673380572-9
A2: Student Name | B2: กฤติธี ศรีใสย์ | K2: Student ID | L2: 673380572-9
A3: Section | K3: Student Name | L3: กฤติธี ศรีใสย์
K4: Section | L4: 04
A5: Use case ID/ Req. ID | B5: Scenario ID | C5: Test Scenario | D5: No. of Test Cases | E5: Pass | F5: Fail | G5: No run | H5: Block | I5: Remark / Defect ID
A6: REQ-01 | B6: TS001 | C6: Room management (Service) | D6: =COUNTIF('Test Case Design & Test Results'!$A$10:$A$189,B6) -> 10 | E6: =COUNTIFS('Test Case Design & Test Results'!$A$10:$A$189,B6,'Test Case Design & Test Results'!$G$10:$G$189,"Pass") -> 10 | F6: =COUNTIFS('Test Case Design & Test Results'!$A$10:$A$189,B6,'Test Case Design & Test Results'!$G$10:$G$189,"Fail") -> 0 | G6: =COUNTIFS('Test Case Design & Test Results'!$A$10:$A$189,B6,'Test Case Design & Test Results'!$G$10:$G$189,"No run") -> 0 | H6: =COUNTIFS('Test Case Design & Test Results'!$A$10:$A$189,B6,'Test Case Design & Test Results'!$G$10:$G$189,"Block") -> 0 | I6: D004
A7: REQ-02 | B7: TS002 | C7: Equipment management (Service) | D7: =COUNTIF('Test Case Design & Test Results'!$A$10:$A$189,B7) -> 12 | E7: =COUNTIFS('Test Case Design & Test Results'!$A$10:$A$189,B7,'Test Case Design & Test Results'!$G$10:$G$189,"Pass") -> 12 | F7: =COUNTIFS('Test Case Design & Test Results'!$A$10:$A$189,B7,'Test Case Design & Test Results'!$G$10:$G$189,"Fail") -> 0 | G7: =COUNTIFS('Test Case Design & Test Results'!$A$10:$A$189,B7,'Test Case Design & Test Results'!$G$10:$G$189,"No run") -> 0 | H7: =COUNTIFS('Test Case Design & Test Results'!$A$10:$A$189,B7,'Test Case Design & Test Results'!$G$10:$G$189,"Block") -> 0 | I7: D003, D004
A8: REQ-03 | B8: TS003 | C8: Booking approval rule (Strategy) | D8: =COUNTIF('Test Case Design & Test Results'!$A$10:$A$189,B8) -> 5 | E8: =COUNTIFS('Test Case Design & Test Results'!$A$10:$A$189,B8,'Test Case Design & Test Results'!$G$10:$G$189,"Pass") -> 5 | F8: =COUNTIFS('Test Case Design & Test Results'!$A$10:$A$189,B8,'Test Case Design & Test Results'!$G$10:$G$189,"Fail") -> 0 | G8: =COUNTIFS('Test Case Design & Test Results'!$A$10:$A$189,B8,'Test Case Design & Test Results'!$G$10:$G$189,"No run") -> 0 | H8: =COUNTIFS('Test Case Design & Test Results'!$A$10:$A$189,B8,'Test Case Design & Test Results'!$G$10:$G$189,"Block") -> 0 | I8: D005, D006
A9: REQ-03 | B9: TS004 | C9: Create booking with approval rule | D9: =COUNTIF('Test Case Design & Test Results'!$A$10:$A$189,B9) -> 2 | E9: =COUNTIFS('Test Case Design & Test Results'!$A$10:$A$189,B9,'Test Case Design & Test Results'!$G$10:$G$189,"Pass") -> 2 | F9: =COUNTIFS('Test Case Design & Test Results'!$A$10:$A$189,B9,'Test Case Design & Test Results'!$G$10:$G$189,"Fail") -> 0 | G9: =COUNTIFS('Test Case Design & Test Results'!$A$10:$A$189,B9,'Test Case Design & Test Results'!$G$10:$G$189,"No run") -> 0 | H9: =COUNTIFS('Test Case Design & Test Results'!$A$10:$A$189,B9,'Test Case Design & Test Results'!$G$10:$G$189,"Block") -> 0 | I9: D005
A10: REQ-04 | B10: TS005 | C10: Room REST API | D10: =COUNTIF('Test Case Design & Test Results'!$A$10:$A$189,B10) -> 6 | E10: =COUNTIFS('Test Case Design & Test Results'!$A$10:$A$189,B10,'Test Case Design & Test Results'!$G$10:$G$189,"Pass") -> 6 | F10: =COUNTIFS('Test Case Design & Test Results'!$A$10:$A$189,B10,'Test Case Design & Test Results'!$G$10:$G$189,"Fail") -> 0 | G10: =COUNTIFS('Test Case Design & Test Results'!$A$10:$A$189,B10,'Test Case Design & Test Results'!$G$10:$G$189,"No run") -> 0 | H10: =COUNTIFS('Test Case Design & Test Results'!$A$10:$A$189,B10,'Test Case Design & Test Results'!$G$10:$G$189,"Block") -> 0 | I10: D001, D002, D004
A11: REQ-05 | B11: TS006 | C11: Equipment REST API | D11: =COUNTIF('Test Case Design & Test Results'!$A$10:$A$189,B11) -> 5 | E11: =COUNTIFS('Test Case Design & Test Results'!$A$10:$A$189,B11,'Test Case Design & Test Results'!$G$10:$G$189,"Pass") -> 5 | F11: =COUNTIFS('Test Case Design & Test Results'!$A$10:$A$189,B11,'Test Case Design & Test Results'!$G$10:$G$189,"Fail") -> 0 | G11: =COUNTIFS('Test Case Design & Test Results'!$A$10:$A$189,B11,'Test Case Design & Test Results'!$G$10:$G$189,"No run") -> 0 | H11: =COUNTIFS('Test Case Design & Test Results'!$A$10:$A$189,B11,'Test Case Design & Test Results'!$G$10:$G$189,"Block") -> 0 | I11: D001, D002, D004
A12: REQ-06 | B12: TS007 | C12: Input validation: Boundary value testing | D12: =COUNTIF('Test Case Design & Test Results'!$A$10:$A$189,B12) -> 109 | E12: =COUNTIFS('Test Case Design & Test Results'!$A$10:$A$189,B12,'Test Case Design & Test Results'!$G$10:$G$189,"Pass") -> 109 | F12: =COUNTIFS('Test Case Design & Test Results'!$A$10:$A$189,B12,'Test Case Design & Test Results'!$G$10:$G$189,"Fail") -> 0 | G12: =COUNTIFS('Test Case Design & Test Results'!$A$10:$A$189,B12,'Test Case Design & Test Results'!$G$10:$G$189,"No run") -> 0 | H12: =COUNTIFS('Test Case Design & Test Results'!$A$10:$A$189,B12,'Test Case Design & Test Results'!$G$10:$G$189,"Block") -> 0 | I12: -
A13: REQ-06 | B13: TS008 | C13: Input validation: Equivalence class testing (single fault) | D13: =COUNTIF('Test Case Design & Test Results'!$A$10:$A$189,B13) -> 25 | E13: =COUNTIFS('Test Case Design & Test Results'!$A$10:$A$189,B13,'Test Case Design & Test Results'!$G$10:$G$189,"Pass") -> 25 | F13: =COUNTIFS('Test Case Design & Test Results'!$A$10:$A$189,B13,'Test Case Design & Test Results'!$G$10:$G$189,"Fail") -> 0 | G13: =COUNTIFS('Test Case Design & Test Results'!$A$10:$A$189,B13,'Test Case Design & Test Results'!$G$10:$G$189,"No run") -> 0 | H13: =COUNTIFS('Test Case Design & Test Results'!$A$10:$A$189,B13,'Test Case Design & Test Results'!$G$10:$G$189,"Block") -> 0 | I13: D001
A14: REQ-01, REQ-02 | B14: TS009 | C14: Integration: API ถึง database จริง | D14: =COUNTIF('Test Case Design & Test Results'!$A$10:$A$189,B14) -> 6 | E14: =COUNTIFS('Test Case Design & Test Results'!$A$10:$A$189,B14,'Test Case Design & Test Results'!$G$10:$G$189,"Pass") -> 6 | F14: =COUNTIFS('Test Case Design & Test Results'!$A$10:$A$189,B14,'Test Case Design & Test Results'!$G$10:$G$189,"Fail") -> 0 | G14: =COUNTIFS('Test Case Design & Test Results'!$A$10:$A$189,B14,'Test Case Design & Test Results'!$G$10:$G$189,"No run") -> 0 | H14: =COUNTIFS('Test Case Design & Test Results'!$A$10:$A$189,B14,'Test Case Design & Test Results'!$G$10:$G$189,"Block") -> 0 | I14: D004
A15: Total | D15: =SUM(D6:D14) -> 180 | E15: =SUM(E6:E14) -> 180 | F15: =SUM(F6:F14) -> 0 | G15: =SUM(G6:G14) -> 0 | H15: =SUM(H6:H14) -> 0 | I15: Test Summary Report

Sheet Defect Summary
A2: No | B2: Defect No | C2: Defect Title | D2: Report Date | E2: Fix date | F2: Reporter | G2: Defect Status | H2: Defect Severity | I2: Defect Priority | J2: Closed By | K2: Defect Details
A3: 1 | B3: D001 | C3: Controller ไม่มี @Valid และ DTO ไม่มี constraint ทำให้ส่งข้อมูลผิดเข้าระบบได้ | D3: 6/10/2569 | E3: 6/10/2569 | F3: ทีม (code review) | G3: Closed | H3: Medium | I3: Medium | J3: กฤติธี ศรีใสย์ | K3: เพิ่ม @NotBlank/@NotNull/@Positive/@Size ใน RoomCreateRequest, EquipmentCreateRequest และใส่ @Valid ใน EquipmentController (POST, PUT) ทดสอบโดย TC-RC02, TC-EC02, TC-EC03
A4: 2 | B4: D002 | C4: URL ของ Equipment ไม่ใช้ prefix /api/v1 เหมือน endpoint อื่น | D4: 6/10/2569 | E4: 6/10/2569 | F4: ทีม (code review) | G4: Closed | H4: Low | I4: Low | J4: กฤติธี ศรีใสย์ | K4: เปลี่ยน /api/equipments เป็น /api/v1/equipments ทดสอบโดย TS006 ทุกเคส
A5: 3 | B5: D003 | C5: หา id ไม่เจอแล้ว throw RuntimeException ทำให้ได้ 500 แทน 404 | D5: 6/10/2569 | E5: 6/10/2569 | F5: ทีม (code review) | G5: Closed | H5: Medium | I5: High | J5: กฤติธี ศรีใสย์ | K5: EquipmentServiceImpl เปลี่ยนเป็น ResourceNotFoundException ผ่าน findEquipmentOrThrow() ทดสอบโดย TC-ES04, TC-ES07, TC-ES10, TC-EC04
A6: 4 | B6: D004 | C6: ลบห้อง/อุปกรณ์ที่มีการจองผูกอยู่ ติด foreign key แล้วได้ 500 แทน 409 | D6: 6/10/2569 | E6: 6/10/2569 | F6: ทีม (code review) | G6: Closed | H6: Medium | I6: High | J6: กฤติธี ศรีใสย์ | K6: delete แล้ว flush() ใน try แล้วแปลง DataIntegrityViolationException เป็น ConflictException และมี handler ใน GlobalExceptionHandler ตอบ 409 ทดสอบโดย TC-RS10, TC-ES12, TC-RC05, TC-EC05
A7: 5 | B7: D005 | C7: Strategy Pattern เขียนไว้แต่ไม่มีใครเรียกใช้ การจองทุกห้องค้างที่ PENDING | D7: 6/10/2569 | E7: 6/10/2569 | F7: ทีม (code review) | G7: Closed | H7: High | I7: High | J7: กฤติธี ศรีใสย์ | K7: BookingServiceImpl.createBooking() เรียก BookingRuleStrategyFactory ตามประเภทห้อง STANDARD อนุมัติอัตโนมัติ VIP รออนุมัติ ทดสอบโดย TC-BK01, TC-BK02
A8: 6 | B8: D006 | C8: ไฟล์ BookingRuleStrategyFactory ไม่มีนามสกุล .java จึงไม่ถูก compile | D8: 6/10/2569 | E8: 6/10/2569 | F8: ทีม (code review) | G8: Closed | H8: High | I8: High | J8: กฤติธี ศรีใสย์ | K8: เปลี่ยนชื่อเป็น BookingRuleStrategyFactory.java ทดสอบโดย TC-ST03 ถึง TC-ST05

Sheet BVT Summary
A2: Test Strategy | B2: No. of Test Cases | C2: Pass | D2: Fail | E2: No run | F2: Block | G2: Remark / Defect ID
A3: Normal Boundary Value Testing (Room) | B3: =COUNTIF('Test Case Design & Test Results'!$B$10:$B$189,"TC-BVR-N??") -> 9 | C3: =COUNTIFS('Test Case Design & Test Results'!$B$10:$B$189,"TC-BVR-N??",'Test Case Design & Test Results'!$G$10:$G$189,"Pass") -> 9 | D3: =COUNTIFS('Test Case Design & Test Results'!$B$10:$B$189,"TC-BVR-N??",'Test Case Design & Test Results'!$G$10:$G$189,"Fail") -> 0 | E3: =COUNTIFS('Test Case Design & Test Results'!$B$10:$B$189,"TC-BVR-N??",'Test Case Design & Test Results'!$G$10:$G$189,"No run") -> 0 | F3: =COUNTIFS('Test Case Design & Test Results'!$B$10:$B$189,"TC-BVR-N??",'Test Case Design & Test Results'!$G$10:$G$189,"Block") -> 0 | G3: 4n+1 = 9
A4: Robustness Testing (Room) | B4: =COUNTIF('Test Case Design & Test Results'!$B$10:$B$189,"TC-BVR-R??") -> 12 | C4: =COUNTIFS('Test Case Design & Test Results'!$B$10:$B$189,"TC-BVR-R??",'Test Case Design & Test Results'!$G$10:$G$189,"Pass") -> 12 | D4: =COUNTIFS('Test Case Design & Test Results'!$B$10:$B$189,"TC-BVR-R??",'Test Case Design & Test Results'!$G$10:$G$189,"Fail") -> 0 | E4: =COUNTIFS('Test Case Design & Test Results'!$B$10:$B$189,"TC-BVR-R??",'Test Case Design & Test Results'!$G$10:$G$189,"No run") -> 0 | F4: =COUNTIFS('Test Case Design & Test Results'!$B$10:$B$189,"TC-BVR-R??",'Test Case Design & Test Results'!$G$10:$G$189,"Block") -> 0 | G4: 6n+1 = 13 (12 + TC-RC06)
A5: Worst-case Testing (Room) | B5: =COUNTIF('Test Case Design & Test Results'!$B$10:$B$189,"TC-BVR-W??") -> 25 | C5: =COUNTIFS('Test Case Design & Test Results'!$B$10:$B$189,"TC-BVR-W??",'Test Case Design & Test Results'!$G$10:$G$189,"Pass") -> 25 | D5: =COUNTIFS('Test Case Design & Test Results'!$B$10:$B$189,"TC-BVR-W??",'Test Case Design & Test Results'!$G$10:$G$189,"Fail") -> 0 | E5: =COUNTIFS('Test Case Design & Test Results'!$B$10:$B$189,"TC-BVR-W??",'Test Case Design & Test Results'!$G$10:$G$189,"No run") -> 0 | F5: =COUNTIFS('Test Case Design & Test Results'!$B$10:$B$189,"TC-BVR-W??",'Test Case Design & Test Results'!$G$10:$G$189,"Block") -> 0 | G5: 5^n = 25
A6: Robust Worst-case Testing (Room) | B6: =COUNTIF('Test Case Design & Test Results'!$B$10:$B$189,"TC-BVR-RW??") -> 42 | C6: =COUNTIFS('Test Case Design & Test Results'!$B$10:$B$189,"TC-BVR-RW??",'Test Case Design & Test Results'!$G$10:$G$189,"Pass") -> 42 | D6: =COUNTIFS('Test Case Design & Test Results'!$B$10:$B$189,"TC-BVR-RW??",'Test Case Design & Test Results'!$G$10:$G$189,"Fail") -> 0 | E6: =COUNTIFS('Test Case Design & Test Results'!$B$10:$B$189,"TC-BVR-RW??",'Test Case Design & Test Results'!$G$10:$G$189,"No run") -> 0 | F6: =COUNTIFS('Test Case Design & Test Results'!$B$10:$B$189,"TC-BVR-RW??",'Test Case Design & Test Results'!$G$10:$G$189,"Block") -> 0 | G6: 7^n = 49 (ทดสอบได้ 42, capacity max+ เกิน Integer)
A7: Normal Boundary Value Testing (Equipment) | B7: =COUNTIF('Test Case Design & Test Results'!$B$10:$B$189,"TC-BVE-N??") -> 9 | C7: =COUNTIFS('Test Case Design & Test Results'!$B$10:$B$189,"TC-BVE-N??",'Test Case Design & Test Results'!$G$10:$G$189,"Pass") -> 9 | D7: =COUNTIFS('Test Case Design & Test Results'!$B$10:$B$189,"TC-BVE-N??",'Test Case Design & Test Results'!$G$10:$G$189,"Fail") -> 0 | E7: =COUNTIFS('Test Case Design & Test Results'!$B$10:$B$189,"TC-BVE-N??",'Test Case Design & Test Results'!$G$10:$G$189,"No run") -> 0 | F7: =COUNTIFS('Test Case Design & Test Results'!$B$10:$B$189,"TC-BVE-N??",'Test Case Design & Test Results'!$G$10:$G$189,"Block") -> 0 | G7: 4n+1 = 9
A8: Robustness Testing (Equipment) | B8: =COUNTIF('Test Case Design & Test Results'!$B$10:$B$189,"TC-BVE-R??") -> 12 | C8: =COUNTIFS('Test Case Design & Test Results'!$B$10:$B$189,"TC-BVE-R??",'Test Case Design & Test Results'!$G$10:$G$189,"Pass") -> 12 | D8: =COUNTIFS('Test Case Design & Test Results'!$B$10:$B$189,"TC-BVE-R??",'Test Case Design & Test Results'!$G$10:$G$189,"Fail") -> 0 | E8: =COUNTIFS('Test Case Design & Test Results'!$B$10:$B$189,"TC-BVE-R??",'Test Case Design & Test Results'!$G$10:$G$189,"No run") -> 0 | F8: =COUNTIFS('Test Case Design & Test Results'!$B$10:$B$189,"TC-BVE-R??",'Test Case Design & Test Results'!$G$10:$G$189,"Block") -> 0 | G8: 6n+1 = 13 (ทดสอบได้ 12)
A9: Total | B9: =SUM(B3:B8) -> 109 | C9: =SUM(C3:C8) -> 109 | D9: =SUM(D3:D8) -> 0 | E9: =SUM(E3:E8) -> 0 | F9: =SUM(F3:F8) -> 0
A11: Robustness capacity max+ (2147483648) ทดสอบที่ระดับ API: TC-RC06 (ดู TS005)

Sheet Normal_Room
A1: Test Case Design and Test Results | J1: ค่า | K1: name (ความยาว) | L1: capacity
J2: min- | K2: 0 | L2: 0
A3: Project Name: | B3: Room - RoomCreateRequest | E3: Student ID: | F3: 673380572-9 | J3: min | K3: 1 | L3: 1
A4: Test Strategy: | B4: Functional testing - Normal Boundary Value Testing | E4: Designer: | F4: กฤติธี ศรีใสย์ | J4: min+ | K4: 2 | L4: 2
A5: Test Environtment: | B5: Java 17, Spring Boot 4.1, JUnit 5, Mockito, Maven Surefire 3.5.6, Windows 11 | E5: Date: | F5: 9/10/2569 | J5: nom | K5: 50 | L5: 10
J6: max- | K6: 99 | L6: 2147483646
A7: Test Case ID | B7: Input | D7: Expected Result | E7: Actual Result | F7: Status (Pass/Fail/No run) | J7: max | K7: 100 | L7: 2147483647
B8: name (ความยาว) | C8: capacity | J8: max+ | K8: 101 | L8: 2147483648 (เกิน Integer)
A9: TC-BVR-N01 | B9: 50 (nom) | C9: 10 (nom) | D9: ผ่าน validation | E9: =IFERROR(INDEX('Test Case Design & Test Results'!$F$10:$F$189,MATCH(A9,'Test Case Design & Test Results'!$B$10:$B$189,0))&"","") -> ผ่าน validation | F9: =IFERROR(INDEX('Test Case Design & Test Results'!$G$10:$G$189,MATCH(A9,'Test Case Design & Test Results'!$B$10:$B$189,0)),"") -> Pass | J9: ช่วงที่ถูกต้อง | K9: [1, 100] | L9: [1, 2147483647]
A10: TC-BVR-N02 | B10: 1 (min) | C10: 10 (nom) | D10: ผ่าน validation | E10: =IFERROR(INDEX('Test Case Design & Test Results'!$F$10:$F$189,MATCH(A10,'Test Case Design & Test Results'!$B$10:$B$189,0))&"","") -> ผ่าน validation | F10: =IFERROR(INDEX('Test Case Design & Test Results'!$G$10:$G$189,MATCH(A10,'Test Case Design & Test Results'!$B$10:$B$189,0)),"") -> Pass
A11: TC-BVR-N03 | B11: 2 (min+) | C11: 10 (nom) | D11: ผ่าน validation | E11: =IFERROR(INDEX('Test Case Design & Test Results'!$F$10:$F$189,MATCH(A11,'Test Case Design & Test Results'!$B$10:$B$189,0))&"","") -> ผ่าน validation | F11: =IFERROR(INDEX('Test Case Design & Test Results'!$G$10:$G$189,MATCH(A11,'Test Case Design & Test Results'!$B$10:$B$189,0)),"") -> Pass
A12: TC-BVR-N04 | B12: 99 (max-) | C12: 10 (nom) | D12: ผ่าน validation | E12: =IFERROR(INDEX('Test Case Design & Test Results'!$F$10:$F$189,MATCH(A12,'Test Case Design & Test Results'!$B$10:$B$189,0))&"","") -> ผ่าน validation | F12: =IFERROR(INDEX('Test Case Design & Test Results'!$G$10:$G$189,MATCH(A12,'Test Case Design & Test Results'!$B$10:$B$189,0)),"") -> Pass
A13: TC-BVR-N05 | B13: 100 (max) | C13: 10 (nom) | D13: ผ่าน validation | E13: =IFERROR(INDEX('Test Case Design & Test Results'!$F$10:$F$189,MATCH(A13,'Test Case Design & Test Results'!$B$10:$B$189,0))&"","") -> ผ่าน validation | F13: =IFERROR(INDEX('Test Case Design & Test Results'!$G$10:$G$189,MATCH(A13,'Test Case Design & Test Results'!$B$10:$B$189,0)),"") -> Pass
A14: TC-BVR-N06 | B14: 50 (nom) | C14: 1 (min) | D14: ผ่าน validation | E14: =IFERROR(INDEX('Test Case Design & Test Results'!$F$10:$F$189,MATCH(A14,'Test Case Design & Test Results'!$B$10:$B$189,0))&"","") -> ผ่าน validation | F14: =IFERROR(INDEX('Test Case Design & Test Results'!$G$10:$G$189,MATCH(A14,'Test Case Design & Test Results'!$B$10:$B$189,0)),"") -> Pass
A15: TC-BVR-N07 | B15: 50 (nom) | C15: 2 (min+) | D15: ผ่าน validation | E15: =IFERROR(INDEX('Test Case Design & Test Results'!$F$10:$F$189,MATCH(A15,'Test Case Design & Test Results'!$B$10:$B$189,0))&"","") -> ผ่าน validation | F15: =IFERROR(INDEX('Test Case Design & Test Results'!$G$10:$G$189,MATCH(A15,'Test Case Design & Test Results'!$B$10:$B$189,0)),"") -> Pass
A16: TC-BVR-N08 | B16: 50 (nom) | C16: 2147483646 (max-) | D16: ผ่าน validation | E16: =IFERROR(INDEX('Test Case Design & Test Results'!$F$10:$F$189,MATCH(A16,'Test Case Design & Test Results'!$B$10:$B$189,0))&"","") -> ผ่าน validation | F16: =IFERROR(INDEX('Test Case Design & Test Results'!$G$10:$G$189,MATCH(A16,'Test Case Design & Test Results'!$B$10:$B$189,0)),"") -> Pass
A17: TC-BVR-N09 | B17: 50 (nom) | C17: 2147483647 (max) | D17: ผ่าน validation | E17: =IFERROR(INDEX('Test Case Design & Test Results'!$F$10:$F$189,MATCH(A17,'Test Case Design & Test Results'!$B$10:$B$189,0))&"","") -> ผ่าน validation | F17: =IFERROR(INDEX('Test Case Design & Test Results'!$G$10:$G$189,MATCH(A17,'Test Case Design & Test Results'!$B$10:$B$189,0)),"") -> Pass

Sheet Robustness_Room
A1: Test Case Design and Test Results | J1: ค่า | K1: name (ความยาว) | L1: capacity
J2: min- | K2: 0 | L2: 0
A3: Project Name: | B3: Room - RoomCreateRequest | E3: Student ID: | F3: 673380572-9 | J3: min | K3: 1 | L3: 1
A4: Test Strategy: | B4: Functional testing - Robustness Testing | E4: Designer: | F4: กฤติธี ศรีใสย์ | J4: min+ | K4: 2 | L4: 2
A5: Test Environtment: | B5: Java 17, Spring Boot 4.1, JUnit 5, Mockito, Maven Surefire 3.5.6, Windows 11 | E5: Date: | F5: 9/10/2569 | J5: nom | K5: 50 | L5: 10
J6: max- | K6: 99 | L6: 2147483646
A7: Test Case ID | B7: Input | D7: Expected Result | E7: Actual Result | F7: Status (Pass/Fail/No run) | J7: max | K7: 100 | L7: 2147483647
B8: name (ความยาว) | C8: capacity | J8: max+ | K8: 101 | L8: 2147483648 (เกิน Integer)
A9: TC-BVR-R01 | B9: 50 (nom) | C9: 10 (nom) | D9: ผ่าน validation | E9: =IFERROR(INDEX('Test Case Design & Test Results'!$F$10:$F$189,MATCH(A9,'Test Case Design & Test Results'!$B$10:$B$189,0))&"","") -> ผ่าน validation | F9: =IFERROR(INDEX('Test Case Design & Test Results'!$G$10:$G$189,MATCH(A9,'Test Case Design & Test Results'!$B$10:$B$189,0)),"") -> Pass | J9: ช่วงที่ถูกต้อง | K9: [1, 100] | L9: [1, 2147483647]
A10: TC-BVR-R02 | B10: 1 (min) | C10: 10 (nom) | D10: ผ่าน validation | E10: =IFERROR(INDEX('Test Case Design & Test Results'!$F$10:$F$189,MATCH(A10,'Test Case Design & Test Results'!$B$10:$B$189,0))&"","") -> ผ่าน validation | F10: =IFERROR(INDEX('Test Case Design & Test Results'!$G$10:$G$189,MATCH(A10,'Test Case Design & Test Results'!$B$10:$B$189,0)),"") -> Pass
A11: TC-BVR-R03 | B11: 2 (min+) | C11: 10 (nom) | D11: ผ่าน validation | E11: =IFERROR(INDEX('Test Case Design & Test Results'!$F$10:$F$189,MATCH(A11,'Test Case Design & Test Results'!$B$10:$B$189,0))&"","") -> ผ่าน validation | F11: =IFERROR(INDEX('Test Case Design & Test Results'!$G$10:$G$189,MATCH(A11,'Test Case Design & Test Results'!$B$10:$B$189,0)),"") -> Pass
A12: TC-BVR-R04 | B12: 99 (max-) | C12: 10 (nom) | D12: ผ่าน validation | E12: =IFERROR(INDEX('Test Case Design & Test Results'!$F$10:$F$189,MATCH(A12,'Test Case Design & Test Results'!$B$10:$B$189,0))&"","") -> ผ่าน validation | F12: =IFERROR(INDEX('Test Case Design & Test Results'!$G$10:$G$189,MATCH(A12,'Test Case Design & Test Results'!$B$10:$B$189,0)),"") -> Pass
A13: TC-BVR-R05 | B13: 100 (max) | C13: 10 (nom) | D13: ผ่าน validation | E13: =IFERROR(INDEX('Test Case Design & Test Results'!$F$10:$F$189,MATCH(A13,'Test Case Design & Test Results'!$B$10:$B$189,0))&"","") -> ผ่าน validation | F13: =IFERROR(INDEX('Test Case Design & Test Results'!$G$10:$G$189,MATCH(A13,'Test Case Design & Test Results'!$B$10:$B$189,0)),"") -> Pass
A14: TC-BVR-R06 | B14: 50 (nom) | C14: 1 (min) | D14: ผ่าน validation | E14: =IFERROR(INDEX('Test Case Design & Test Results'!$F$10:$F$189,MATCH(A14,'Test Case Design & Test Results'!$B$10:$B$189,0))&"","") -> ผ่าน validation | F14: =IFERROR(INDEX('Test Case Design & Test Results'!$G$10:$G$189,MATCH(A14,'Test Case Design & Test Results'!$B$10:$B$189,0)),"") -> Pass
A15: TC-BVR-R07 | B15: 50 (nom) | C15: 2 (min+) | D15: ผ่าน validation | E15: =IFERROR(INDEX('Test Case Design & Test Results'!$F$10:$F$189,MATCH(A15,'Test Case Design & Test Results'!$B$10:$B$189,0))&"","") -> ผ่าน validation | F15: =IFERROR(INDEX('Test Case Design & Test Results'!$G$10:$G$189,MATCH(A15,'Test Case Design & Test Results'!$B$10:$B$189,0)),"") -> Pass
A16: TC-BVR-R08 | B16: 50 (nom) | C16: 2147483646 (max-) | D16: ผ่าน validation | E16: =IFERROR(INDEX('Test Case Design & Test Results'!$F$10:$F$189,MATCH(A16,'Test Case Design & Test Results'!$B$10:$B$189,0))&"","") -> ผ่าน validation | F16: =IFERROR(INDEX('Test Case Design & Test Results'!$G$10:$G$189,MATCH(A16,'Test Case Design & Test Results'!$B$10:$B$189,0)),"") -> Pass
A17: TC-BVR-R09 | B17: 50 (nom) | C17: 2147483647 (max) | D17: ผ่าน validation | E17: =IFERROR(INDEX('Test Case Design & Test Results'!$F$10:$F$189,MATCH(A17,'Test Case Design & Test Results'!$B$10:$B$189,0))&"","") -> ผ่าน validation | F17: =IFERROR(INDEX('Test Case Design & Test Results'!$G$10:$G$189,MATCH(A17,'Test Case Design & Test Results'!$B$10:$B$189,0)),"") -> Pass
A18: TC-BVR-R10 | B18: 0 (min-) | C18: 10 (nom) | D18: ไม่ผ่าน validation | E18: =IFERROR(INDEX('Test Case Design & Test Results'!$F$10:$F$189,MATCH(A18,'Test Case Design & Test Results'!$B$10:$B$189,0))&"","") -> ไม่ผ่าน validation (name) | F18: =IFERROR(INDEX('Test Case Design & Test Results'!$G$10:$G$189,MATCH(A18,'Test Case Design & Test Results'!$B$10:$B$189,0)),"") -> Pass
A19: TC-BVR-R11 | B19: 101 (max+) | C19: 10 (nom) | D19: ไม่ผ่าน validation | E19: =IFERROR(INDEX('Test Case Design & Test Results'!$F$10:$F$189,MATCH(A19,'Test Case Design & Test Results'!$B$10:$B$189,0))&"","") -> ไม่ผ่าน validation (name) | F19: =IFERROR(INDEX('Test Case Design & Test Results'!$G$10:$G$189,MATCH(A19,'Test Case Design & Test Results'!$B$10:$B$189,0)),"") -> Pass
A20: TC-BVR-R12 | B20: 50 (nom) | C20: 0 (min-) | D20: ไม่ผ่าน validation | E20: =IFERROR(INDEX('Test Case Design & Test Results'!$F$10:$F$189,MATCH(A20,'Test Case Design & Test Results'!$B$10:$B$189,0))&"","") -> ไม่ผ่าน validation (capacity) | F20: =IFERROR(INDEX('Test Case Design & Test Results'!$G$10:$G$189,MATCH(A20,'Test Case Design & Test Results'!$B$10:$B$189,0)),"") -> Pass

Sheet WorstCase_Room
A1: Test Case Design and Test Results | J1: ค่า | K1: name (ความยาว) | L1: capacity
J2: min- | K2: 0 | L2: 0
A3: Project Name: | B3: Room - RoomCreateRequest | E3: Student ID: | F3: 673380572-9 | J3: min | K3: 1 | L3: 1
A4: Test Strategy: | B4: Functional testing - Worst-case Testing | E4: Designer: | F4: กฤติธี ศรีใสย์ | J4: min+ | K4: 2 | L4: 2
A5: Test Environtment: | B5: Java 17, Spring Boot 4.1, JUnit 5, Mockito, Maven Surefire 3.5.6, Windows 11 | E5: Date: | F5: 9/10/2569 | J5: nom | K5: 50 | L5: 10
J6: max- | K6: 99 | L6: 2147483646
A7: Test Case ID | B7: Input | D7: Expected Result | E7: Actual Result | F7: Status (Pass/Fail/No run) | J7: max | K7: 100 | L7: 2147483647
B8: name (ความยาว) | C8: capacity | J8: max+ | K8: 101 | L8: 2147483648 (เกิน Integer)
A9: TC-BVR-W01 | B9: 1 (min) | C9: 1 (min) | D9: ผ่าน validation | E9: =IFERROR(INDEX('Test Case Design & Test Results'!$F$10:$F$189,MATCH(A9,'Test Case Design & Test Results'!$B$10:$B$189,0))&"","") -> ผ่าน validation | F9: =IFERROR(INDEX('Test Case Design & Test Results'!$G$10:$G$189,MATCH(A9,'Test Case Design & Test Results'!$B$10:$B$189,0)),"") -> Pass | J9: ช่วงที่ถูกต้อง | K9: [1, 100] | L9: [1, 2147483647]
A10: TC-BVR-W02 | B10: 1 (min) | C10: 2 (min+) | D10: ผ่าน validation | E10: =IFERROR(INDEX('Test Case Design & Test Results'!$F$10:$F$189,MATCH(A10,'Test Case Design & Test Results'!$B$10:$B$189,0))&"","") -> ผ่าน validation | F10: =IFERROR(INDEX('Test Case Design & Test Results'!$G$10:$G$189,MATCH(A10,'Test Case Design & Test Results'!$B$10:$B$189,0)),"") -> Pass
A11: TC-BVR-W03 | B11: 1 (min) | C11: 10 (nom) | D11: ผ่าน validation | E11: =IFERROR(INDEX('Test Case Design & Test Results'!$F$10:$F$189,MATCH(A11,'Test Case Design & Test Results'!$B$10:$B$189,0))&"","") -> ผ่าน validation | F11: =IFERROR(INDEX('Test Case Design & Test Results'!$G$10:$G$189,MATCH(A11,'Test Case Design & Test Results'!$B$10:$B$189,0)),"") -> Pass
A12: TC-BVR-W04 | B12: 1 (min) | C12: 2147483646 (max-) | D12: ผ่าน validation | E12: =IFERROR(INDEX('Test Case Design & Test Results'!$F$10:$F$189,MATCH(A12,'Test Case Design & Test Results'!$B$10:$B$189,0))&"","") -> ผ่าน validation | F12: =IFERROR(INDEX('Test Case Design & Test Results'!$G$10:$G$189,MATCH(A12,'Test Case Design & Test Results'!$B$10:$B$189,0)),"") -> Pass
A13: TC-BVR-W05 | B13: 1 (min) | C13: 2147483647 (max) | D13: ผ่าน validation | E13: =IFERROR(INDEX('Test Case Design & Test Results'!$F$10:$F$189,MATCH(A13,'Test Case Design & Test Results'!$B$10:$B$189,0))&"","") -> ผ่าน validation | F13: =IFERROR(INDEX('Test Case Design & Test Results'!$G$10:$G$189,MATCH(A13,'Test Case Design & Test Results'!$B$10:$B$189,0)),"") -> Pass
A14: TC-BVR-W06 | B14: 2 (min+) | C14: 1 (min) | D14: ผ่าน validation | E14: =IFERROR(INDEX('Test Case Design & Test Results'!$F$10:$F$189,MATCH(A14,'Test Case Design & Test Results'!$B$10:$B$189,0))&"","") -> ผ่าน validation | F14: =IFERROR(INDEX('Test Case Design & Test Results'!$G$10:$G$189,MATCH(A14,'Test Case Design & Test Results'!$B$10:$B$189,0)),"") -> Pass
A15: TC-BVR-W07 | B15: 2 (min+) | C15: 2 (min+) | D15: ผ่าน validation | E15: =IFERROR(INDEX('Test Case Design & Test Results'!$F$10:$F$189,MATCH(A15,'Test Case Design & Test Results'!$B$10:$B$189,0))&"","") -> ผ่าน validation | F15: =IFERROR(INDEX('Test Case Design & Test Results'!$G$10:$G$189,MATCH(A15,'Test Case Design & Test Results'!$B$10:$B$189,0)),"") -> Pass
A16: TC-BVR-W08 | B16: 2 (min+) | C16: 10 (nom) | D16: ผ่าน validation | E16: =IFERROR(INDEX('Test Case Design & Test Results'!$F$10:$F$189,MATCH(A16,'Test Case Design & Test Results'!$B$10:$B$189,0))&"","") -> ผ่าน validation | F16: =IFERROR(INDEX('Test Case Design & Test Results'!$G$10:$G$189,MATCH(A16,'Test Case Design & Test Results'!$B$10:$B$189,0)),"") -> Pass
A17: TC-BVR-W09 | B17: 2 (min+) | C17: 2147483646 (max-) | D17: ผ่าน validation | E17: =IFERROR(INDEX('Test Case Design & Test Results'!$F$10:$F$189,MATCH(A17,'Test Case Design & Test Results'!$B$10:$B$189,0))&"","") -> ผ่าน validation | F17: =IFERROR(INDEX('Test Case Design & Test Results'!$G$10:$G$189,MATCH(A17,'Test Case Design & Test Results'!$B$10:$B$189,0)),"") -> Pass
A18: TC-BVR-W10 | B18: 2 (min+) | C18: 2147483647 (max) | D18: ผ่าน validation | E18: =IFERROR(INDEX('Test Case Design & Test Results'!$F$10:$F$189,MATCH(A18,'Test Case Design & Test Results'!$B$10:$B$189,0))&"","") -> ผ่าน validation | F18: =IFERROR(INDEX('Test Case Design & Test Results'!$G$10:$G$189,MATCH(A18,'Test Case Design & Test Results'!$B$10:$B$189,0)),"") -> Pass
A19: TC-BVR-W11 | B19: 50 (nom) | C19: 1 (min) | D19: ผ่าน validation | E19: =IFERROR(INDEX('Test Case Design & Test Results'!$F$10:$F$189,MATCH(A19,'Test Case Design & Test Results'!$B$10:$B$189,0))&"","") -> ผ่าน validation | F19: =IFERROR(INDEX('Test Case Design & Test Results'!$G$10:$G$189,MATCH(A19,'Test Case Design & Test Results'!$B$10:$B$189,0)),"") -> Pass
A20: TC-BVR-W12 | B20: 50 (nom) | C20: 2 (min+) | D20: ผ่าน validation | E20: =IFERROR(INDEX('Test Case Design & Test Results'!$F$10:$F$189,MATCH(A20,'Test Case Design & Test Results'!$B$10:$B$189,0))&"","") -> ผ่าน validation | F20: =IFERROR(INDEX('Test Case Design & Test Results'!$G$10:$G$189,MATCH(A20,'Test Case Design & Test Results'!$B$10:$B$189,0)),"") -> Pass
A21: TC-BVR-W13 | B21: 50 (nom) | C21: 10 (nom) | D21: ผ่าน validation | E21: =IFERROR(INDEX('Test Case Design & Test Results'!$F$10:$F$189,MATCH(A21,'Test Case Design & Test Results'!$B$10:$B$189,0))&"","") -> ผ่าน validation | F21: =IFERROR(INDEX('Test Case Design & Test Results'!$G$10:$G$189,MATCH(A21,'Test Case Design & Test Results'!$B$10:$B$189,0)),"") -> Pass
... A33: TC-BVR-W25 | B33: 100 (max) | C33: 2147483647 (max) | D33: ผ่าน validation | E33: =IFERROR(INDEX('Test Case Design & Test Results'!$F$10:$F$189,MATCH(A33,'Test Case Design & Test Results'!$B$10:$B$189,0))&"","") -> ผ่าน validation | F33: =IFERROR(INDEX('Test Case Design & Test Results'!$G$10:$G$189,MATCH(A33,'Test Case Design & Test Results'!$B$10:$B$189,0)),"") -> Pass

Sheet RobustWorst_Room
A1: Test Case Design and Test Results | J1: ค่า | K1: name (ความยาว) | L1: capacity
J2: min- | K2: 0 | L2: 0
A3: Project Name: | B3: Room - RoomCreateRequest | E3: Student ID: | F3: 673380572-9 | J3: min | K3: 1 | L3: 1
A4: Test Strategy: | B4: Functional testing - Robust Worst-case Testing | E4: Designer: | F4: กฤติธี ศรีใสย์ | J4: min+ | K4: 2 | L4: 2
A5: Test Environtment: | B5: Java 17, Spring Boot 4.1, JUnit 5, Mockito, Maven Surefire 3.5.6, Windows 11 | E5: Date: | F5: 9/10/2569 | J5: nom | K5: 50 | L5: 10
J6: max- | K6: 99 | L6: 2147483646
A7: Test Case ID | B7: Input | D7: Expected Result | E7: Actual Result | F7: Status (Pass/Fail/No run) | J7: max | K7: 100 | L7: 2147483647
B8: name (ความยาว) | C8: capacity | J8: max+ | K8: 101 | L8: 2147483648 (เกิน Integer)
A9: TC-BVR-RW01 | B9: 0 (min-) | C9: 0 (min-) | D9: ไม่ผ่าน validation | E9: =IFERROR(INDEX('Test Case Design & Test Results'!$F$10:$F$189,MATCH(A9,'Test Case Design & Test Results'!$B$10:$B$189,0))&"","") -> ไม่ผ่าน validation (name) | F9: =IFERROR(INDEX('Test Case Design & Test Results'!$G$10:$G$189,MATCH(A9,'Test Case Design & Test Results'!$B$10:$B$189,0)),"") -> Pass | J9: ช่วงที่ถูกต้อง | K9: [1, 100] | L9: [1, 2147483647]
A10: TC-BVR-RW02 | B10: 0 (min-) | C10: 1 (min) | D10: ไม่ผ่าน validation | E10: =IFERROR(INDEX('Test Case Design & Test Results'!$F$10:$F$189,MATCH(A10,'Test Case Design & Test Results'!$B$10:$B$189,0))&"","") -> ไม่ผ่าน validation (name) | F10: =IFERROR(INDEX('Test Case Design & Test Results'!$G$10:$G$189,MATCH(A10,'Test Case Design & Test Results'!$B$10:$B$189,0)),"") -> Pass
A11: TC-BVR-RW03 | B11: 0 (min-) | C11: 2 (min+) | D11: ไม่ผ่าน validation | E11: =IFERROR(INDEX('Test Case Design & Test Results'!$F$10:$F$189,MATCH(A11,'Test Case Design & Test Results'!$B$10:$B$189,0))&"","") -> ไม่ผ่าน validation (name) | F11: =IFERROR(INDEX('Test Case Design & Test Results'!$G$10:$G$189,MATCH(A11,'Test Case Design & Test Results'!$B$10:$B$189,0)),"") -> Pass
A12: TC-BVR-RW04 | B12: 0 (min-) | C12: 10 (nom) | D12: ไม่ผ่าน validation | E12: =IFERROR(INDEX('Test Case Design & Test Results'!$F$10:$F$189,MATCH(A12,'Test Case Design & Test Results'!$B$10:$B$189,0))&"","") -> ไม่ผ่าน validation (name) | F12: =IFERROR(INDEX('Test Case Design & Test Results'!$G$10:$G$189,MATCH(A12,'Test Case Design & Test Results'!$B$10:$B$189,0)),"") -> Pass
A13: TC-BVR-RW05 | B13: 0 (min-) | C13: 2147483646 (max-) | D13: ไม่ผ่าน validation | E13: =IFERROR(INDEX('Test Case Design & Test Results'!$F$10:$F$189,MATCH(A13,'Test Case Design & Test Results'!$B$10:$B$189,0))&"","") -> ไม่ผ่าน validation (name) | F13: =IFERROR(INDEX('Test Case Design & Test Results'!$G$10:$G$189,MATCH(A13,'Test Case Design & Test Results'!$B$10:$B$189,0)),"") -> Pass
A14: TC-BVR-RW06 | B14: 0 (min-) | C14: 2147483647 (max) | D14: ไม่ผ่าน validation | E14: =IFERROR(INDEX('Test Case Design & Test Results'!$F$10:$F$189,MATCH(A14,'Test Case Design & Test Results'!$B$10:$B$189,0))&"","") -> ไม่ผ่าน validation (name) | F14: =IFERROR(INDEX('Test Case Design & Test Results'!$G$10:$G$189,MATCH(A14,'Test Case Design & Test Results'!$B$10:$B$189,0)),"") -> Pass
A15: TC-BVR-RW07 | B15: 1 (min) | C15: 0 (min-) | D15: ไม่ผ่าน validation | E15: =IFERROR(INDEX('Test Case Design & Test Results'!$F$10:$F$189,MATCH(A15,'Test Case Design & Test Results'!$B$10:$B$189,0))&"","") -> ไม่ผ่าน validation (capacity) | F15: =IFERROR(INDEX('Test Case Design & Test Results'!$G$10:$G$189,MATCH(A15,'Test Case Design & Test Results'!$B$10:$B$189,0)),"") -> Pass
A16: TC-BVR-RW08 | B16: 1 (min) | C16: 1 (min) | D16: ผ่าน validation | E16: =IFERROR(INDEX('Test Case Design & Test Results'!$F$10:$F$189,MATCH(A16,'Test Case Design & Test Results'!$B$10:$B$189,0))&"","") -> ผ่าน validation | F16: =IFERROR(INDEX('Test Case Design & Test Results'!$G$10:$G$189,MATCH(A16,'Test Case Design & Test Results'!$B$10:$B$189,0)),"") -> Pass
A17: TC-BVR-RW09 | B17: 1 (min) | C17: 2 (min+) | D17: ผ่าน validation | E17: =IFERROR(INDEX('Test Case Design & Test Results'!$F$10:$F$189,MATCH(A17,'Test Case Design & Test Results'!$B$10:$B$189,0))&"","") -> ผ่าน validation | F17: =IFERROR(INDEX('Test Case Design & Test Results'!$G$10:$G$189,MATCH(A17,'Test Case Design & Test Results'!$B$10:$B$189,0)),"") -> Pass
A18: TC-BVR-RW10 | B18: 1 (min) | C18: 10 (nom) | D18: ผ่าน validation | E18: =IFERROR(INDEX('Test Case Design & Test Results'!$F$10:$F$189,MATCH(A18,'Test Case Design & Test Results'!$B$10:$B$189,0))&"","") -> ผ่าน validation | F18: =IFERROR(INDEX('Test Case Design & Test Results'!$G$10:$G$189,MATCH(A18,'Test Case Design & Test Results'!$B$10:$B$189,0)),"") -> Pass
A19: TC-BVR-RW11 | B19: 1 (min) | C19: 2147483646 (max-) | D19: ผ่าน validation | E19: =IFERROR(INDEX('Test Case Design & Test Results'!$F$10:$F$189,MATCH(A19,'Test Case Design & Test Results'!$B$10:$B$189,0))&"","") -> ผ่าน validation | F19: =IFERROR(INDEX('Test Case Design & Test Results'!$G$10:$G$189,MATCH(A19,'Test Case Design & Test Results'!$B$10:$B$189,0)),"") -> Pass
A20: TC-BVR-RW12 | B20: 1 (min) | C20: 2147483647 (max) | D20: ผ่าน validation | E20: =IFERROR(INDEX('Test Case Design & Test Results'!$F$10:$F$189,MATCH(A20,'Test Case Design & Test Results'!$B$10:$B$189,0))&"","") -> ผ่าน validation | F20: =IFERROR(INDEX('Test Case Design & Test Results'!$G$10:$G$189,MATCH(A20,'Test Case Design & Test Results'!$B$10:$B$189,0)),"") -> Pass
A21: TC-BVR-RW13 | B21: 2 (min+) | C21: 0 (min-) | D21: ไม่ผ่าน validation | E21: =IFERROR(INDEX('Test Case Design & Test Results'!$F$10:$F$189,MATCH(A21,'Test Case Design & Test Results'!$B$10:$B$189,0))&"","") -> ไม่ผ่าน validation (capacity) | F21: =IFERROR(INDEX('Test Case Design & Test Results'!$G$10:$G$189,MATCH(A21,'Test Case Design & Test Results'!$B$10:$B$189,0)),"") -> Pass
... A50: TC-BVR-RW42 | B50: 101 (max+) | C50: 2147483647 (max) | D50: ไม่ผ่าน validation | E50: =IFERROR(INDEX('Test Case Design & Test Results'!$F$10:$F$189,MATCH(A50,'Test Case Design & Test Results'!$B$10:$B$189,0))&"","") -> ไม่ผ่าน validation (name) | F50: =IFERROR(INDEX('Test Case Design & Test Results'!$G$10:$G$189,MATCH(A50,'Test Case Design & Test Results'!$B$10:$B$189,0)),"") -> Pass

Sheet Normal_Equipment
A1: Test Case Design and Test Results | J1: ค่า | K1: name (ความยาว) | L1: totalQuantity
J2: min- | K2: 0 | L2: -1
A3: Project Name: | B3: Equipment - EquipmentCreateRequest | E3: Student ID: | F3: 673380572-9 | J3: min | K3: 1 | L3: 0
A4: Test Strategy: | B4: Functional testing - Normal Boundary Value Testing | E4: Designer: | F4: กฤติธี ศรีใสย์ | J4: min+ | K4: 2 | L4: 1
A5: Test Environtment: | B5: Java 17, Spring Boot 4.1, JUnit 5, Mockito, Maven Surefire 3.5.6, Windows 11 | E5: Date: | F5: 9/10/2569 | J5: nom | K5: 50 | L5: 5
J6: max- | K6: 99 | L6: 2147483646
A7: Test Case ID | B7: Input | D7: Expected Result | E7: Actual Result | F7: Status (Pass/Fail/No run) | J7: max | K7: 100 | L7: 2147483647
B8: name (ความยาว) | C8: totalQuantity | J8: max+ | K8: 101 | L8: 2147483648 (เกิน Integer)
A9: TC-BVE-N01 | B9: 50 (nom) | C9: 5 (nom) | D9: ผ่าน validation | E9: =IFERROR(INDEX('Test Case Design & Test Results'!$F$10:$F$189,MATCH(A9,'Test Case Design & Test Results'!$B$10:$B$189,0))&"","") -> ผ่าน validation | F9: =IFERROR(INDEX('Test Case Design & Test Results'!$G$10:$G$189,MATCH(A9,'Test Case Design & Test Results'!$B$10:$B$189,0)),"") -> Pass | J9: ช่วงที่ถูกต้อง | K9: [1, 100] | L9: [0, 2147483647]
A10: TC-BVE-N02 | B10: 1 (min) | C10: 5 (nom) | D10: ผ่าน validation | E10: =IFERROR(INDEX('Test Case Design & Test Results'!$F$10:$F$189,MATCH(A10,'Test Case Design & Test Results'!$B$10:$B$189,0))&"","") -> ผ่าน validation | F10: =IFERROR(INDEX('Test Case Design & Test Results'!$G$10:$G$189,MATCH(A10,'Test Case Design & Test Results'!$B$10:$B$189,0)),"") -> Pass
A11: TC-BVE-N03 | B11: 2 (min+) | C11: 5 (nom) | D11: ผ่าน validation | E11: =IFERROR(INDEX('Test Case Design & Test Results'!$F$10:$F$189,MATCH(A11,'Test Case Design & Test Results'!$B$10:$B$189,0))&"","") -> ผ่าน validation | F11: =IFERROR(INDEX('Test Case Design & Test Results'!$G$10:$G$189,MATCH(A11,'Test Case Design & Test Results'!$B$10:$B$189,0)),"") -> Pass
A12: TC-BVE-N04 | B12: 99 (max-) | C12: 5 (nom) | D12: ผ่าน validation | E12: =IFERROR(INDEX('Test Case Design & Test Results'!$F$10:$F$189,MATCH(A12,'Test Case Design & Test Results'!$B$10:$B$189,0))&"","") -> ผ่าน validation | F12: =IFERROR(INDEX('Test Case Design & Test Results'!$G$10:$G$189,MATCH(A12,'Test Case Design & Test Results'!$B$10:$B$189,0)),"") -> Pass
A13: TC-BVE-N05 | B13: 100 (max) | C13: 5 (nom) | D13: ผ่าน validation | E13: =IFERROR(INDEX('Test Case Design & Test Results'!$F$10:$F$189,MATCH(A13,'Test Case Design & Test Results'!$B$10:$B$189,0))&"","") -> ผ่าน validation | F13: =IFERROR(INDEX('Test Case Design & Test Results'!$G$10:$G$189,MATCH(A13,'Test Case Design & Test Results'!$B$10:$B$189,0)),"") -> Pass
A14: TC-BVE-N06 | B14: 50 (nom) | C14: 0 (min) | D14: ผ่าน validation | E14: =IFERROR(INDEX('Test Case Design & Test Results'!$F$10:$F$189,MATCH(A14,'Test Case Design & Test Results'!$B$10:$B$189,0))&"","") -> ผ่าน validation | F14: =IFERROR(INDEX('Test Case Design & Test Results'!$G$10:$G$189,MATCH(A14,'Test Case Design & Test Results'!$B$10:$B$189,0)),"") -> Pass
A15: TC-BVE-N07 | B15: 50 (nom) | C15: 1 (min+) | D15: ผ่าน validation | E15: =IFERROR(INDEX('Test Case Design & Test Results'!$F$10:$F$189,MATCH(A15,'Test Case Design & Test Results'!$B$10:$B$189,0))&"","") -> ผ่าน validation | F15: =IFERROR(INDEX('Test Case Design & Test Results'!$G$10:$G$189,MATCH(A15,'Test Case Design & Test Results'!$B$10:$B$189,0)),"") -> Pass
A16: TC-BVE-N08 | B16: 50 (nom) | C16: 2147483646 (max-) | D16: ผ่าน validation | E16: =IFERROR(INDEX('Test Case Design & Test Results'!$F$10:$F$189,MATCH(A16,'Test Case Design & Test Results'!$B$10:$B$189,0))&"","") -> ผ่าน validation | F16: =IFERROR(INDEX('Test Case Design & Test Results'!$G$10:$G$189,MATCH(A16,'Test Case Design & Test Results'!$B$10:$B$189,0)),"") -> Pass
A17: TC-BVE-N09 | B17: 50 (nom) | C17: 2147483647 (max) | D17: ผ่าน validation | E17: =IFERROR(INDEX('Test Case Design & Test Results'!$F$10:$F$189,MATCH(A17,'Test Case Design & Test Results'!$B$10:$B$189,0))&"","") -> ผ่าน validation | F17: =IFERROR(INDEX('Test Case Design & Test Results'!$G$10:$G$189,MATCH(A17,'Test Case Design & Test Results'!$B$10:$B$189,0)),"") -> Pass

Sheet Robustness_Equipment
A1: Test Case Design and Test Results | J1: ค่า | K1: name (ความยาว) | L1: totalQuantity
J2: min- | K2: 0 | L2: -1
A3: Project Name: | B3: Equipment - EquipmentCreateRequest | E3: Student ID: | F3: 673380572-9 | J3: min | K3: 1 | L3: 0
A4: Test Strategy: | B4: Functional testing - Robustness Testing | E4: Designer: | F4: กฤติธี ศรีใสย์ | J4: min+ | K4: 2 | L4: 1
A5: Test Environtment: | B5: Java 17, Spring Boot 4.1, JUnit 5, Mockito, Maven Surefire 3.5.6, Windows 11 | E5: Date: | F5: 9/10/2569 | J5: nom | K5: 50 | L5: 5
J6: max- | K6: 99 | L6: 2147483646
A7: Test Case ID | B7: Input | D7: Expected Result | E7: Actual Result | F7: Status (Pass/Fail/No run) | J7: max | K7: 100 | L7: 2147483647
B8: name (ความยาว) | C8: totalQuantity | J8: max+ | K8: 101 | L8: 2147483648 (เกิน Integer)
A9: TC-BVE-R01 | B9: 50 (nom) | C9: 5 (nom) | D9: ผ่าน validation | E9: =IFERROR(INDEX('Test Case Design & Test Results'!$F$10:$F$189,MATCH(A9,'Test Case Design & Test Results'!$B$10:$B$189,0))&"","") -> ผ่าน validation | F9: =IFERROR(INDEX('Test Case Design & Test Results'!$G$10:$G$189,MATCH(A9,'Test Case Design & Test Results'!$B$10:$B$189,0)),"") -> Pass | J9: ช่วงที่ถูกต้อง | K9: [1, 100] | L9: [0, 2147483647]
A10: TC-BVE-R02 | B10: 1 (min) | C10: 5 (nom) | D10: ผ่าน validation | E10: =IFERROR(INDEX('Test Case Design & Test Results'!$F$10:$F$189,MATCH(A10,'Test Case Design & Test Results'!$B$10:$B$189,0))&"","") -> ผ่าน validation | F10: =IFERROR(INDEX('Test Case Design & Test Results'!$G$10:$G$189,MATCH(A10,'Test Case Design & Test Results'!$B$10:$B$189,0)),"") -> Pass
A11: TC-BVE-R03 | B11: 2 (min+) | C11: 5 (nom) | D11: ผ่าน validation | E11: =IFERROR(INDEX('Test Case Design & Test Results'!$F$10:$F$189,MATCH(A11,'Test Case Design & Test Results'!$B$10:$B$189,0))&"","") -> ผ่าน validation | F11: =IFERROR(INDEX('Test Case Design & Test Results'!$G$10:$G$189,MATCH(A11,'Test Case Design & Test Results'!$B$10:$B$189,0)),"") -> Pass
A12: TC-BVE-R04 | B12: 99 (max-) | C12: 5 (nom) | D12: ผ่าน validation | E12: =IFERROR(INDEX('Test Case Design & Test Results'!$F$10:$F$189,MATCH(A12,'Test Case Design & Test Results'!$B$10:$B$189,0))&"","") -> ผ่าน validation | F12: =IFERROR(INDEX('Test Case Design & Test Results'!$G$10:$G$189,MATCH(A12,'Test Case Design & Test Results'!$B$10:$B$189,0)),"") -> Pass
A13: TC-BVE-R05 | B13: 100 (max) | C13: 5 (nom) | D13: ผ่าน validation | E13: =IFERROR(INDEX('Test Case Design & Test Results'!$F$10:$F$189,MATCH(A13,'Test Case Design & Test Results'!$B$10:$B$189,0))&"","") -> ผ่าน validation | F13: =IFERROR(INDEX('Test Case Design & Test Results'!$G$10:$G$189,MATCH(A13,'Test Case Design & Test Results'!$B$10:$B$189,0)),"") -> Pass
A14: TC-BVE-R06 | B14: 50 (nom) | C14: 0 (min) | D14: ผ่าน validation | E14: =IFERROR(INDEX('Test Case Design & Test Results'!$F$10:$F$189,MATCH(A14,'Test Case Design & Test Results'!$B$10:$B$189,0))&"","") -> ผ่าน validation | F14: =IFERROR(INDEX('Test Case Design & Test Results'!$G$10:$G$189,MATCH(A14,'Test Case Design & Test Results'!$B$10:$B$189,0)),"") -> Pass
A15: TC-BVE-R07 | B15: 50 (nom) | C15: 1 (min+) | D15: ผ่าน validation | E15: =IFERROR(INDEX('Test Case Design & Test Results'!$F$10:$F$189,MATCH(A15,'Test Case Design & Test Results'!$B$10:$B$189,0))&"","") -> ผ่าน validation | F15: =IFERROR(INDEX('Test Case Design & Test Results'!$G$10:$G$189,MATCH(A15,'Test Case Design & Test Results'!$B$10:$B$189,0)),"") -> Pass
A16: TC-BVE-R08 | B16: 50 (nom) | C16: 2147483646 (max-) | D16: ผ่าน validation | E16: =IFERROR(INDEX('Test Case Design & Test Results'!$F$10:$F$189,MATCH(A16,'Test Case Design & Test Results'!$B$10:$B$189,0))&"","") -> ผ่าน validation | F16: =IFERROR(INDEX('Test Case Design & Test Results'!$G$10:$G$189,MATCH(A16,'Test Case Design & Test Results'!$B$10:$B$189,0)),"") -> Pass
A17: TC-BVE-R09 | B17: 50 (nom) | C17: 2147483647 (max) | D17: ผ่าน validation | E17: =IFERROR(INDEX('Test Case Design & Test Results'!$F$10:$F$189,MATCH(A17,'Test Case Design & Test Results'!$B$10:$B$189,0))&"","") -> ผ่าน validation | F17: =IFERROR(INDEX('Test Case Design & Test Results'!$G$10:$G$189,MATCH(A17,'Test Case Design & Test Results'!$B$10:$B$189,0)),"") -> Pass
A18: TC-BVE-R10 | B18: 0 (min-) | C18: 5 (nom) | D18: ไม่ผ่าน validation | E18: =IFERROR(INDEX('Test Case Design & Test Results'!$F$10:$F$189,MATCH(A18,'Test Case Design & Test Results'!$B$10:$B$189,0))&"","") -> ไม่ผ่าน validation (name) | F18: =IFERROR(INDEX('Test Case Design & Test Results'!$G$10:$G$189,MATCH(A18,'Test Case Design & Test Results'!$B$10:$B$189,0)),"") -> Pass
A19: TC-BVE-R11 | B19: 101 (max+) | C19: 5 (nom) | D19: ไม่ผ่าน validation | E19: =IFERROR(INDEX('Test Case Design & Test Results'!$F$10:$F$189,MATCH(A19,'Test Case Design & Test Results'!$B$10:$B$189,0))&"","") -> ไม่ผ่าน validation (name) | F19: =IFERROR(INDEX('Test Case Design & Test Results'!$G$10:$G$189,MATCH(A19,'Test Case Design & Test Results'!$B$10:$B$189,0)),"") -> Pass
A20: TC-BVE-R12 | B20: 50 (nom) | C20: -1 (min-) | D20: ไม่ผ่าน validation | E20: =IFERROR(INDEX('Test Case Design & Test Results'!$F$10:$F$189,MATCH(A20,'Test Case Design & Test Results'!$B$10:$B$189,0))&"","") -> ไม่ผ่าน validation (totalQuantity) | F20: =IFERROR(INDEX('Test Case Design & Test Results'!$G$10:$G$189,MATCH(A20,'Test Case Design & Test Results'!$B$10:$B$189,0)),"") -> Pass

Sheet EC Summary
A2: Project | B2: No. of Test Cases | C2: Pass | D2: Fail | E2: No run | F2: Block | G2: Remark / Defect ID
A3: Room - RoomCreateRequest | B3: =COUNTIF('Test Case Design & Test Results'!$B$10:$B$189,"TC-ECR-???") -> 15 | C3: =COUNTIFS('Test Case Design & Test Results'!$B$10:$B$189,"TC-ECR-???",'Test Case Design & Test Results'!$G$10:$G$189,"Pass") -> 15 | D3: =COUNTIFS('Test Case Design & Test Results'!$B$10:$B$189,"TC-ECR-???",'Test Case Design & Test Results'!$G$10:$G$189,"Fail") -> 0 | E3: =COUNTIFS('Test Case Design & Test Results'!$B$10:$B$189,"TC-ECR-???",'Test Case Design & Test Results'!$G$10:$G$189,"No run") -> 0 | F3: =COUNTIFS('Test Case Design & Test Results'!$B$10:$B$189,"TC-ECR-???",'Test Case Design & Test Results'!$G$10:$G$189,"Block") -> 0
A4: Equipment - EquipmentCreateRequest | B4: =COUNTIF('Test Case Design & Test Results'!$B$10:$B$189,"TC-ECE-???") -> 10 | C4: =COUNTIFS('Test Case Design & Test Results'!$B$10:$B$189,"TC-ECE-???",'Test Case Design & Test Results'!$G$10:$G$189,"Pass") -> 10 | D4: =COUNTIFS('Test Case Design & Test Results'!$B$10:$B$189,"TC-ECE-???",'Test Case Design & Test Results'!$G$10:$G$189,"Fail") -> 0 | E4: =COUNTIFS('Test Case Design & Test Results'!$B$10:$B$189,"TC-ECE-???",'Test Case Design & Test Results'!$G$10:$G$189,"No run") -> 0 | F4: =COUNTIFS('Test Case Design & Test Results'!$B$10:$B$189,"TC-ECE-???",'Test Case Design & Test Results'!$G$10:$G$189,"Block") -> 0
A5: Total | B5: =SUM(B3:B4) -> 25 | C5: =SUM(C3:C4) -> 25 | D5: =SUM(D3:D4) -> 0 | E5: =SUM(E3:E4) -> 0 | F5: =SUM(F3:F4) -> 0
A7: EC21–EC26 (id มี/ไม่มี, มี/ไม่มีการจอง, RoomType มี/ไม่มี strategy) ทดสอบใน TS001–TS006, TS009 และ Decision Table

Sheet 1_Room
A1: Equivalence Class Design
A2: Valid EC | F2: Invalid EC
A3: EC ID | B3: Condition | F3: EC ID | G3: Condition
A4: EC1 | B4: name ไม่ว่าง และยาว 1-100 ตัวอักษร | F4: EC2 | G4: name ว่าง / มีแต่ช่องว่าง / null
A5: EC4 | B5: capacity เป็นจำนวนเต็ม ≥ 1 | F5: EC3 | G5: name ยาวเกิน 100 ตัวอักษร
A6: EC7 | B6: floor เป็น null หรือยาว ≤ 20 ตัวอักษร | F6: EC5 | G6: capacity ≤ 0
A7: EC9 | B7: roomType = STANDARD หรือ VIP | F7: EC6 | G7: capacity = null
A8: EC11 | B8: status = AVAILABLE หรือ MAINTENANCE | F8: EC8 | G8: floor ยาวเกิน 20 ตัวอักษร
F9: EC10 | G9: roomType = null
F10: EC12 | G10: status = null
A12: Test Case Design and Test Results
A14: Project Name: | B14: Room - RoomCreateRequest | H14: Student ID: | I14: 673380572-9
A15: Test Strategy: | B15: Functional testing - Weak Robust Equivalence Class Testing (single fault) | H15: Designer: | I15: กฤติธี ศรีใสย์
A16: Test Environtment: | B16: Java 17, Spring Boot 4.1, JUnit 5, Mockito, Maven Surefire 3.5.6, Windows 11 | H16: Date: | I16: 9/10/2569
A18: Test Case ID | B18: Input | G18: Expected Result | H18: Actual Result | I18: Status (Pass/Fail/No run)
B19: name | C19: capacity | D19: floor | E19: roomType | F19: status
A20: TC-ECR-V01 | B20: Room A | C20: 10 | D20: 2 | E20: STANDARD | F20: AVAILABLE | G20: ไม่มี violation | H20: =IFERROR(INDEX('Test Case Design & Test Results'!$F$10:$F$189,MATCH(A20,'Test Case Design & Test Results'!$B$10:$B$189,0))&"","") -> ไม่มี violation | I20: =IFERROR(INDEX('Test Case Design & Test Results'!$G$10:$G$189,MATCH(A20,'Test Case Design & Test Results'!$B$10:$B$189,0)),"") -> Pass
A21: TC-ECR-V02 | B21: Room A | C21: 10 | D21: null | E21: STANDARD | F21: AVAILABLE | G21: ไม่มี violation | H21: =IFERROR(INDEX('Test Case Design & Test Results'!$F$10:$F$189,MATCH(A21,'Test Case Design & Test Results'!$B$10:$B$189,0))&"","") -> ไม่มี violation | I21: =IFERROR(INDEX('Test Case Design & Test Results'!$G$10:$G$189,MATCH(A21,'Test Case Design & Test Results'!$B$10:$B$189,0)),"") -> Pass
A22: TC-ECR-V03 | B22: Room A | C22: 10 | D22: F × 20 | E22: STANDARD | F22: AVAILABLE | G22: ไม่มี violation | H22: =IFERROR(INDEX('Test Case Design & Test Results'!$F$10:$F$189,MATCH(A22,'Test Case Design & Test Results'!$B$10:$B$189,0))&"","") -> ไม่มี violation | I22: =IFERROR(INDEX('Test Case Design & Test Results'!$G$10:$G$189,MATCH(A22,'Test Case Design & Test Results'!$B$10:$B$189,0)),"") -> Pass
A23: TC-ECR-V04 | B23: Room A | C23: 10 | D23: 2 | E23: VIP | F23: AVAILABLE | G23: ไม่มี violation | H23: =IFERROR(INDEX('Test Case Design & Test Results'!$F$10:$F$189,MATCH(A23,'Test Case Design & Test Results'!$B$10:$B$189,0))&"","") -> ไม่มี violation | I23: =IFERROR(INDEX('Test Case Design & Test Results'!$G$10:$G$189,MATCH(A23,'Test Case Design & Test Results'!$B$10:$B$189,0)),"") -> Pass
A24: TC-ECR-V05 | B24: Room A | C24: 10 | D24: 2 | E24: STANDARD | F24: MAINTENANCE | G24: ไม่มี violation | H24: =IFERROR(INDEX('Test Case Design & Test Results'!$F$10:$F$189,MATCH(A24,'Test Case Design & Test Results'!$B$10:$B$189,0))&"","") -> ไม่มี violation | I24: =IFERROR(INDEX('Test Case Design & Test Results'!$G$10:$G$189,MATCH(A24,'Test Case Design & Test Results'!$B$10:$B$189,0)),"") -> Pass
A25: TC-ECR-I01 | B25: "" | C25: 10 | D25: 2 | E25: STANDARD | F25: AVAILABLE | G25: violation 1 รายการ ที่ field name | H25: =IFERROR(INDEX('Test Case Design & Test Results'!$F$10:$F$189,MATCH(A25,'Test Case Design & Test Results'!$B$10:$B$189,0))&"","") -> violation 1 รายการ ที่ field name | I25: =IFERROR(INDEX('Test Case Design & Test Results'!$G$10:$G$189,MATCH(A25,'Test Case Design & Test Results'!$B$10:$B$189,0)),"") -> Pass
A26: TC-ECR-I02 | B26: " " | C26: 10 | D26: 2 | E26: STANDARD | F26: AVAILABLE | G26: violation 1 รายการ ที่ field name | H26: =IFERROR(INDEX('Test Case Design & Test Results'!$F$10:$F$189,MATCH(A26,'Test Case Design & Test Results'!$B$10:$B$189,0))&"","") -> violation 1 รายการ ที่ field name | I26: =IFERROR(INDEX('Test Case Design & Test Results'!$G$10:$G$189,MATCH(A26,'Test Case Design & Test Results'!$B$10:$B$189,0)),"") -> Pass
A27: TC-ECR-I03 | B27: null | C27: 10 | D27: 2 | E27: STANDARD | F27: AVAILABLE | G27: violation 1 รายการ ที่ field name | H27: =IFERROR(INDEX('Test Case Design & Test Results'!$F$10:$F$189,MATCH(A27,'Test Case Design & Test Results'!$B$10:$B$189,0))&"","") -> violation 1 รายการ ที่ field name | I27: =IFERROR(INDEX('Test Case Design & Test Results'!$G$10:$G$189,MATCH(A27,'Test Case Design & Test Results'!$B$10:$B$189,0)),"") -> Pass
A28: TC-ECR-I04 | B28: A × 101 | C28: 10 | D28: 2 | E28: STANDARD | F28: AVAILABLE | G28: violation 1 รายการ ที่ field name | H28: =IFERROR(INDEX('Test Case Design & Test Results'!$F$10:$F$189,MATCH(A28,'Test Case Design & Test Results'!$B$10:$B$189,0))&"","") -> violation 1 รายการ ที่ field name | I28: =IFERROR(INDEX('Test Case Design & Test Results'!$G$10:$G$189,MATCH(A28,'Test Case Design & Test Results'!$B$10:$B$189,0)),"") -> Pass
A29: TC-ECR-I05 | B29: Room A | C29: 0 | D29: 2 | E29: STANDARD | F29: AVAILABLE | G29: violation 1 รายการ ที่ field capacity | H29: =IFERROR(INDEX('Test Case Design & Test Results'!$F$10:$F$189,MATCH(A29,'Test Case Design & Test Results'!$B$10:$B$189,0))&"","") -> violation 1 รายการ ที่ field capacity | I29: =IFERROR(INDEX('Test Case Design & Test Results'!$G$10:$G$189,MATCH(A29,'Test Case Design & Test Results'!$B$10:$B$189,0)),"") -> Pass
A30: TC-ECR-I06 | B30: Room A | C30: -1 | D30: 2 | E30: STANDARD | F30: AVAILABLE | G30: violation 1 รายการ ที่ field capacity | H30: =IFERROR(INDEX('Test Case Design & Test Results'!$F$10:$F$189,MATCH(A30,'Test Case Design & Test Results'!$B$10:$B$189,0))&"","") -> violation 1 รายการ ที่ field capacity | I30: =IFERROR(INDEX('Test Case Design & Test Results'!$G$10:$G$189,MATCH(A30,'Test Case Design & Test Results'!$B$10:$B$189,0)),"") -> Pass
A31: TC-ECR-I07 | B31: Room A | C31: null | D31: 2 | E31: STANDARD | F31: AVAILABLE | G31: violation 1 รายการ ที่ field capacity | H31: =IFERROR(INDEX('Test Case Design & Test Results'!$F$10:$F$189,MATCH(A31,'Test Case Design & Test Results'!$B$10:$B$189,0))&"","") -> violation 1 รายการ ที่ field capacity | I31: =IFERROR(INDEX('Test Case Design & Test Results'!$G$10:$G$189,MATCH(A31,'Test Case Design & Test Results'!$B$10:$B$189,0)),"") -> Pass
A32: TC-ECR-I08 | B32: Room A | C32: 10 | D32: F × 21 | E32: STANDARD | F32: AVAILABLE | G32: violation 1 รายการ ที่ field floor | H32: =IFERROR(INDEX('Test Case Design & Test Results'!$F$10:$F$189,MATCH(A32,'Test Case Design & Test Results'!$B$10:$B$189,0))&"","") -> violation 1 รายการ ที่ field floor | I32: =IFERROR(INDEX('Test Case Design & Test Results'!$G$10:$G$189,MATCH(A32,'Test Case Design & Test Results'!$B$10:$B$189,0)),"") -> Pass
A33: TC-ECR-I09 | B33: Room A | C33: 10 | D33: 2 | E33: null | F33: AVAILABLE | G33: violation 1 รายการ ที่ field roomType | H33: =IFERROR(INDEX('Test Case Design & Test Results'!$F$10:$F$189,MATCH(A33,'Test Case Design & Test Results'!$B$10:$B$189,0))&"","") -> violation 1 รายการ ที่ field roomType | I33: =IFERROR(INDEX('Test Case Design & Test Results'!$G$10:$G$189,MATCH(A33,'Test Case Design & Test Results'!$B$10:$B$189,0)),"") -> Pass
A34: TC-ECR-I10 | B34: Room A | C34: 10 | D34: 2 | E34: STANDARD | F34: null | G34: violation 1 รายการ ที่ field status | H34: =IFERROR(INDEX('Test Case Design & Test Results'!$F$10:$F$189,MATCH(A34,'Test Case Design & Test Results'!$B$10:$B$189,0))&"","") -> violation 1 รายการ ที่ field status | I34: =IFERROR(INDEX('Test Case Design & Test Results'!$G$10:$G$189,MATCH(A34,'Test Case Design & Test Results'!$B$10:$B$189,0)),"") -> Pass

Sheet 2_Equipment
A1: Equivalence Class Design
A2: Valid EC | F2: Invalid EC
A3: EC ID | B3: Condition | F3: EC ID | G3: Condition
A4: EC13 | B4: name ไม่ว่าง และยาว 1-100 ตัวอักษร | F4: EC14 | G4: name ว่าง / มีแต่ช่องว่าง
A5: EC16 | B5: totalQuantity เป็นจำนวนเต็ม ≥ 0 | F5: EC15 | G5: name ยาวเกิน 100 ตัวอักษร
A6: EC19 | B6: category เป็น null หรือยาว ≤ 50 ตัวอักษร | F6: EC17 | G6: totalQuantity < 0
F7: EC18 | G7: totalQuantity = null
F8: EC20 | G8: category ยาวเกิน 50 ตัวอักษร
A10: Test Case Design and Test Results
A12: Project Name: | B12: Equipment - EquipmentCreateRequest | F12: Student ID: | G12: 673380572-9
A13: Test Strategy: | B13: Functional testing - Weak Robust Equivalence Class Testing (single fault) | F13: Designer: | G13: กฤติธี ศรีใสย์
A14: Test Environtment: | B14: Java 17, Spring Boot 4.1, JUnit 5, Mockito, Maven Surefire 3.5.6, Windows 11 | F14: Date: | G14: 9/10/2569
A16: Test Case ID | B16: Input | E16: Expected Result | F16: Actual Result | G16: Status (Pass/Fail/No run)
B17: name | C17: totalQuantity | D17: category
A18: TC-ECE-V01 | B18: Projector | C18: 5 | D18: Display | E18: ไม่มี violation | F18: =IFERROR(INDEX('Test Case Design & Test Results'!$F$10:$F$189,MATCH(A18,'Test Case Design & Test Results'!$B$10:$B$189,0))&"","") -> ไม่มี violation | G18: =IFERROR(INDEX('Test Case Design & Test Results'!$G$10:$G$189,MATCH(A18,'Test Case Design & Test Results'!$B$10:$B$189,0)),"") -> Pass
A19: TC-ECE-V02 | B19: Projector | C19: 0 | D19: Display | E19: ไม่มี violation | F19: =IFERROR(INDEX('Test Case Design & Test Results'!$F$10:$F$189,MATCH(A19,'Test Case Design & Test Results'!$B$10:$B$189,0))&"","") -> ไม่มี violation | G19: =IFERROR(INDEX('Test Case Design & Test Results'!$G$10:$G$189,MATCH(A19,'Test Case Design & Test Results'!$B$10:$B$189,0)),"") -> Pass
A20: TC-ECE-V03 | B20: Projector | C20: 5 | D20: null | E20: ไม่มี violation | F20: =IFERROR(INDEX('Test Case Design & Test Results'!$F$10:$F$189,MATCH(A20,'Test Case Design & Test Results'!$B$10:$B$189,0))&"","") -> ไม่มี violation | G20: =IFERROR(INDEX('Test Case Design & Test Results'!$G$10:$G$189,MATCH(A20,'Test Case Design & Test Results'!$B$10:$B$189,0)),"") -> Pass
A21: TC-ECE-V04 | B21: Projector | C21: 5 | D21: C × 50 | E21: ไม่มี violation | F21: =IFERROR(INDEX('Test Case Design & Test Results'!$F$10:$F$189,MATCH(A21,'Test Case Design & Test Results'!$B$10:$B$189,0))&"","") -> ไม่มี violation | G21: =IFERROR(INDEX('Test Case Design & Test Results'!$G$10:$G$189,MATCH(A21,'Test Case Design & Test Results'!$B$10:$B$189,0)),"") -> Pass
A22: TC-ECE-I01 | B22: "" | C22: 5 | D22: Display | E22: violation 1 รายการ ที่ field name | F22: =IFERROR(INDEX('Test Case Design & Test Results'!$F$10:$F$189,MATCH(A22,'Test Case Design & Test Results'!$B$10:$B$189,0))&"","") -> violation 1 รายการ ที่ field name | G22: =IFERROR(INDEX('Test Case Design & Test Results'!$G$10:$G$189,MATCH(A22,'Test Case Design & Test Results'!$B$10:$B$189,0)),"") -> Pass
A23: TC-ECE-I02 | B23: " " | C23: 5 | D23: Display | E23: violation 1 รายการ ที่ field name | F23: =IFERROR(INDEX('Test Case Design & Test Results'!$F$10:$F$189,MATCH(A23,'Test Case Design & Test Results'!$B$10:$B$189,0))&"","") -> violation 1 รายการ ที่ field name | G23: =IFERROR(INDEX('Test Case Design & Test Results'!$G$10:$G$189,MATCH(A23,'Test Case Design & Test Results'!$B$10:$B$189,0)),"") -> Pass
A24: TC-ECE-I03 | B24: P × 101 | C24: 5 | D24: Display | E24: violation 1 รายการ ที่ field name | F24: =IFERROR(INDEX('Test Case Design & Test Results'!$F$10:$F$189,MATCH(A24,'Test Case Design & Test Results'!$B$10:$B$189,0))&"","") -> violation 1 รายการ ที่ field name | G24: =IFERROR(INDEX('Test Case Design & Test Results'!$G$10:$G$189,MATCH(A24,'Test Case Design & Test Results'!$B$10:$B$189,0)),"") -> Pass
A25: TC-ECE-I04 | B25: Projector | C25: -1 | D25: Display | E25: violation 1 รายการ ที่ field totalQuantity | F25: =IFERROR(INDEX('Test Case Design & Test Results'!$F$10:$F$189,MATCH(A25,'Test Case Design & Test Results'!$B$10:$B$189,0))&"","") -> violation 1 รายการ ที่ field totalQuantity | G25: =IFERROR(INDEX('Test Case Design & Test Results'!$G$10:$G$189,MATCH(A25,'Test Case Design & Test Results'!$B$10:$B$189,0)),"") -> Pass
A26: TC-ECE-I05 | B26: Projector | C26: null | D26: Display | E26: violation 1 รายการ ที่ field totalQuantity | F26: =IFERROR(INDEX('Test Case Design & Test Results'!$F$10:$F$189,MATCH(A26,'Test Case Design & Test Results'!$B$10:$B$189,0))&"","") -> violation 1 รายการ ที่ field totalQuantity | G26: =IFERROR(INDEX('Test Case Design & Test Results'!$G$10:$G$189,MATCH(A26,'Test Case Design & Test Results'!$B$10:$B$189,0)),"") -> Pass
A27: TC-ECE-I06 | B27: Projector | C27: 5 | D27: C × 51 | E27: violation 1 รายการ ที่ field category | F27: =IFERROR(INDEX('Test Case Design & Test Results'!$F$10:$F$189,MATCH(A27,'Test Case Design & Test Results'!$B$10:$B$189,0))&"","") -> violation 1 รายการ ที่ field category | G27: =IFERROR(INDEX('Test Case Design & Test Results'!$G$10:$G$189,MATCH(A27,'Test Case Design & Test Results'!$B$10:$B$189,0)),"") -> Pass

Sheet Limited Entry Decision Table
A1: DT1: ลบห้อง / อุปกรณ์ (deleteRoom, deleteEquipment)
A2: Condition | B2: Rule#1 | C2: Rule#2 | D2: Rule#3 | E2: Rule#4
A3: C1: id มีอยู่ในระบบ | B3: T | C3: T | D3: F | E3: F
A4: C2: มีการจองผูกอยู่ (foreign key) | B4: T | C4: F | D4: T | E4: F
A5: Action
A6: A1: throw ConflictException → 409 | B6: X
A7: A2: ลบสำเร็จ → 204 | C7: X
A8: A3: throw ResourceNotFoundException → 404 | E8: X
A9: Impossible | D9: X
A12: DT2: แก้ไขอุปกรณ์ (updateEquipment)
A13: Condition | B13: Rule#1 | C13: Rule#2 | D13: Rule#3
A14: C1: id มีอยู่ในระบบ | B14: T | C14: T | D14: F
A15: C2: totalQuantity ≥ 0 | B15: T | C15: F | D15: -
A16: Action
A17: A1: อัปเดตและ save สำเร็จ | B17: X
A18: A2: throw IllegalArgumentException และไม่ save | C18: X
A19: A3: throw ResourceNotFoundException → 404 | D19: X
A20: Impossible
A23: DT3: กฎการอนุมัติการจอง (createBooking + Strategy)
